<mujoco>
    <compiler meshdir="./mesh" texturedir="./textures" />

     <option cone="pyramidal" impratio="100" iterations="1" ls_iterations="5">
        <flag eulerdamp="disable"/>
     </option>

    <default>
        <default class="quadruped">
            <geom type="mesh" material="robot_material" friction="0.6" margin="0.001" condim="1"/>
            <joint axis="0 0 1" type="hinge" damping="2" armature="0.01"/>
            <position   ctrlrange="-1 1"
                        forcerange="-1.1 1.1"
                        kp="150"
                        kv="10"
                        timeconst="0.02"
                        ctrllimited="true"
                        forcelimited="true"
            />

            <default class="hip">
                <joint range="0 90"/>
                <position ctrlrange="-1 1"/>
            </default>

            <default class="knee">
                <joint range="-120 45"/>
                <position ctrlrange="-1 1"/>
            </default>

            <default class="ankle">
                <joint range="-90 90"/>
                <position ctrlrange="-1 1"/>
            </default>
        </default>


    </default>

    <worldbody>
        <body name="FRAME" pos="0.0 0.0 0.1" childclass="quadruped">
            <joint name="free_joint" type="free"/>
            <geom name="FRAME geom" mesh="FRAME"/>

            <body name="fema_1" pos="-0.0336 0.02700 0.0195">
                <joint name="hip_1" class="hip"/>
                <geom name="fema_1 geom" mesh="FEMA"/>

                <body name="shin_1" pos="0.0269 0.0381 -0.0358" euler="0 90 0">
                    <joint name="knee_1" class="knee"/>
                    <geom name="shin_1 geom" mesh="SHIN"/>

                    <body name="foot_1" pos="0.0 0.0798 -0.0006" >
                        <joint name="ankle_1" class="ankle"/>
                        <geom name="foot_1 geom" mesh="FOOT"/>
                    </body>
                </body>
            </body>

            <body name="fema_2" pos="-0.02700 -0.0336 0.0195" euler="0 0 90">
                <joint name="hip_2" class="hip"/>
                <geom name="fema_2 geom" mesh="FEMA"/>

                <body name="shin_2" pos="0.0269 0.0381 -0.0358" euler="0 90 0">
                    <joint name="knee_2" class="knee"/>
                    <geom name="shin_2 geom" mesh="SHIN"/>

                    <body name="foot_2" pos="0.0 0.0798 -0.0006" >
                        <joint name="ankle_2" class="ankle"/>
                        <geom name="foot_2 geom" mesh="FOOT"/>
                    </body>
                </body>
            </body>

            <body name="fema_3" pos="0.0336 -0.02700 0.0195" euler="0 0 180">
                <joint name="hip_3" class="hip"/>
                <geom name="fema_3 geom" mesh="FEMA"/>

                <body name="shin_3" pos="0.0269 0.0381 -0.0358" euler="0 90 0">
                    <joint name="knee_3" class="knee"/>
                    <geom name="shin_3 geom" mesh="SHIN"/>

                    <body name="foot_3" pos="0.0 0.0798 -0.0006">
                        <joint name="ankle_3" class="ankle"/>
                        <geom name="foot_3 geom" mesh="FOOT"/>
                    </body>
                </body>
            </body>

            <body name="fema_4" pos="0.0270 0.0336 0.0195" euler="0 0 -90">
                <joint name="hip_4" class="hip"/>
                <geom name="fema_4 geom" mesh="FEMA"/>

                <body name="shin_4" pos="0.0269 0.0381 -0.0358" euler="0 90 0">
                    <joint name="knee_4" class="knee"/>
                    <geom name="shin_4 geom" mesh="SHIN"/>

                    <body name="foot_4" pos="0.0 0.0798 -0.0006">
                        <joint name="ankle_4" class="ankle"/>
                        <geom name="foot_4 geom" mesh="FOOT"/>
                    </body>
                </body>
            </body>
        </body>
    </worldbody>
    <asset>
        <mesh name="FRAME" file="FRAME.obj"/>
        <mesh name="FEMA" file="FEMA.obj"/>
        <mesh name="SHIN" file="SHIN.obj"/>
        <mesh name="FOOT" file="FOOT.obj"/>

        <texture name="robot_texture" type="2d" file="colors.png"/>
        <material name="robot_material" texture="robot_texture" texuniform="true" rgba="1 1 1 1"/>
    </asset>
    <actuator>
        <position joint="hip_1" class="hip"/>
        <position joint="knee_1" class="knee"/>
        <position joint="ankle_1" class="ankle"/>

        <position joint="hip_2" class="hip"/>
        <position joint="knee_2" class="knee"/>
        <position joint="ankle_2" class="ankle"/>

        <position joint="hip_3" class="hip"/>
        <position joint="knee_3" class="knee"/>
        <position joint="ankle_3" class="ankle"/>

        <position joint="hip_4" class="hip"/>
        <position joint="knee_4" class="knee"/>
        <position joint="ankle_4" class="ankle"/>
    </actuator>
</mujoco>