<mujoco>
    <compiler angle="degree" meshdir="./mesh" texturedir="./textures" />

    <option integrator="implicitfast" />

    <default>
        <default class="quadruped">
            <geom type="mesh" material="robot_material" friction="0.6" margin="0.001"/>
            <joint axis="0 0 1" type="hinge" damping="0.2" armature="0.001"/>
            <position   ctrlrange="-1 1"
                        forcerange="-1.71 1.71"
                        kp="100"
                        kv="1"
                        timeconst="0.01"
                        ctrllimited="true"
                        forcelimited="true"
            />

            <!-- Gear ratio and adapted force range is set to map the control range from -1, 1 to -pi/2, pi/2 -->
            <!-- Original force range is -1.1, 1.1  with gear ratio to 1 and range from -pi/, pi/2 -->
            <!-- Damping controls actual speed of the servo (mesurements are needed to set this value) -->
            <!-- With this setup damping indicates the speed of the servo in s/60° -->

            <default class="hip">
                <joint range="-45 45" ref="-45"/>
                <position ctrlrange="-0.5 0.5" gear="0.64"/>
            </default>

            <default class="knee">
                <joint range="-45 120" ref="37.5"/>
                <position ctrlrange="-0.91 0.91" gear="0.64"/>
            </default>

            <default class="ankle">
                <joint range="-90 90" ref="0"/>
                <position ctrlrange="-1 1" gear="0.64"/>
            </default>

            <default class="servo">
                <geom mesh="SERVO" mass="0.056"/>
            </default>

            <default class="frame">
                <geom mesh="FRAME" mass="0.018"/>
            </default>

            <default class="fema">
                <geom mesh="FEMA" mass="0.022"/>
            </default>

            <default class="shin">
                <geom mesh="SHIN" mass="0.013"/>
            </default>

            <default class="foot">
                <geom mesh="FOOT" mass="0.07"/>
            </default>
        </default>
    </default>

    <worldbody>
        <body name="FRAME" pos="0.0 0.0 0.13" childclass="quadruped">
            <joint name="free_joint" type="free"/>
            <geom name="FRAME geom" class="frame"/>
            <geom name="hip_servo_1 geom" class="servo" group="1" pos="-0.0334 0.0163 -0.0046"/>
            <geom name="hip_servo_2 geom" class="servo" group="2" pos="-0.0163 -0.0334 -0.0046" euler="0 0 90"/>
            <geom name="hip_servo_3 geom" class="servo" group="3" pos="0.0334 -0.0163 -0.0046" euler="0 0 180"/>
            <geom name="hip_servo_4 geom" class="servo" group="4" pos="0.0163 0.0334 -0.0046" euler="0 0 -90"/>
            <site name="FRAME"/>

            <body name="fema_1" pos="-0.0336 0.02700 0.0195">
                <joint name="hip_1" class="hip"/>
                <geom name="fema_1 geom" class="fema" group="1"/>
                <geom name="knee_servo_1 geom" class="servo" group="1" pos="0.003 0.0381 -0.0251" quat="0.5 -0.5 0.5 -0.5"/>

                <body name="shin_1" pos="0.0269 0.0381 -0.0358" euler="0 90 0">
                    <joint name="knee_1" class="knee"/>
                    <geom name="shin_1 geom" class="shin" group="1"/>

                    <body name="foot_1" pos="0.0 0.0798 -0.0006">
                        <joint name="ankle_1" class="ankle"/>
                        <geom name="foot_1 geom" class="foot" group="1"/>
                        <geom name="ankle_servo_1 geom" class="servo" group="1" pos="0.0 0.011 -0.0234" euler="0 0 180"/>

                    </body>
                </body>
            </body>

            <body name="fema_2" pos="-0.02700 -0.0336 0.0195" euler="0 0 90">
                <joint name="hip_2" class="hip"/>
                <geom name="fema_2 geom" class="fema" group="2"/>
                <geom name="knee_servo_2 geom" class="servo" group="2" pos="0.003 0.0381 -0.0251" quat="0.5 -0.5 0.5 -0.5"/>

                <body name="shin_2" pos="0.0269 0.0381 -0.0358" euler="0 90 0">
                    <joint name="knee_2" class="knee"/>
                    <geom name="shin_2 geom" class="shin" group="2"/>

                    <body name="foot_2" pos="0.0 0.0798 -0.0006">
                        <joint name="ankle_2" class="ankle"/>
                        <geom name="foot_2 geom" class="foot" group="2"/>
                        <geom name="ankle_servo_2 geom" class="servo" group="2" pos="0.0 0.011 -0.0234" euler="0 0 180"/>

                    </body>
                </body>
            </body>

            <body name="fema_3" pos="0.0336 -0.02700 0.0195" euler="0 0 180">
                <joint name="hip_3" class="hip"/>
                <geom name="fema_3 geom" class="fema" group="3"/>
                <geom name="knee_servo_3 geom" class="servo" group="3" pos="0.003 0.0381 -0.0251" quat="0.5 -0.5 0.5 -0.5"/>

                <body name="shin_3" pos="0.0269 0.0381 -0.0358" euler="0 90 0">
                    <joint name="knee_3" class="knee"/>
                    <geom name="shin_3 geom" class="shin" group="3"/>

                    <body name="foot_3" pos="0.0 0.0798 -0.0006">
                        <joint name="ankle_3" class="ankle"/>
                        <geom name="foot_3 geom" class="foot" group="3"/>
                        <geom name="ankle_servo_3 geom" class="servo" group="3" pos="0.0 0.011 -0.0234" euler="0 0 180"/>

                    </body>
                </body>
            </body>

            <body name="fema_4" pos="0.0270 0.0336 0.0195" euler="0 0 -90">
                <joint name="hip_4" class="hip"/>
                <geom name="fema_4 geom" class="fema" group="4"/>
                <geom name="knee_servo_4 geom" class="servo" group="4" pos="0.003 0.0381 -0.0251" quat="0.5 -0.5 0.5 -0.5"/>

                <body name="shin_4" pos="0.0269 0.0381 -0.0358" euler="0 90 0">
                    <joint name="knee_4" class="knee"/>
                    <geom name="shin_4 geom" class="shin" group="4"/>

                    <body name="foot_4" pos="0.0 0.0798 -0.0006">
                        <joint name="ankle_4" class="ankle"/>
                        <geom name="foot_4 geom" class="foot" group="4"/>
                        <geom name="ankle_servo_4 geom" class="servo" group="4" pos="0.0 0.011 -0.0234" euler="0 0 180"/>

                    </body>
                </body>
            </body>
        </body>
    </worldbody>

    <asset>
        <mesh name="FRAME" file="FRAME.obj"/>
        <mesh name="FEMA" file="FEMA.obj"/>
        <mesh name="SHIN" file="SHIN.obj"/>
        <mesh name="FOOT" file="FOOT.obj"/>
        <mesh name="SERVO" file="SERVO.obj"/>

        <texture name="robot_texture" type="2d" file="colors.png"/>
        <material name="robot_material" texture="robot_texture" texuniform="true" rgba="1 1 1 1"/>
    </asset>

    <actuator>
        <position joint="hip_1" class="hip"/>
        <position joint="knee_1" class="knee"/>
        <position joint="ankle_1" class="ankle"/>

        <position joint="hip_2" class="hip"/>
        <position joint="knee_2" class="knee"/>
        <position joint="ankle_2" class="ankle"/>

        <position joint="hip_3" class="hip"/>
        <position joint="knee_3" class="knee"/>
        <position joint="ankle_3" class="ankle"/>

        <position joint="hip_4" class="hip"/>
        <position joint="knee_4" class="knee"/>
        <position joint="ankle_4" class="ankle"/>
    </actuator>

    <sensor>
        <!-- Position sensors for the joints -->

        <!-- Indices 0, 1, 2 -->
        <jointpos joint="hip_1" name="hip_1_sensor"/>
        <jointpos joint="knee_1" name="knee_1_sensor"/>
        <jointpos joint="ankle_1" name="ankle_1_sensor"/>

        <!-- Indices 3, 4, 5 -->
        <jointpos joint="hip_2" name="hip_2_sensor"/>
        <jointpos joint="knee_2" name="knee_2_sensor"/>
        <jointpos joint="ankle_2" name="ankle_2_sensor"/>

        <!-- Indices 6, 7, 8 -->
        <jointpos joint="hip_3" name="hip_3_sensor"/>
        <jointpos joint="knee_3" name="knee_3_sensor"/>
        <jointpos joint="ankle_3" name="ankle_3_sensor"/>

        <!-- Indices 9, 10, 11 -->
        <jointpos joint="hip_4" name="hip_4_sensor"/>
        <jointpos joint="knee_4" name="knee_4_sensor"/>
        <jointpos joint="ankle_4" name="ankle_4_sensor"/>

        <!-- Accelerometer and gyroscope sensors for the body -->

        <!-- Indices 12, 13, 14 -->
        <accelerometer noise="0.01" site="FRAME" name="body_accel"/>
        <!-- Indices 15, 16, 17 -->
        <gyro noise="0.01" site="FRAME" name="body_gyro"/>
        <!-- Indices 18, 19, 20 -->
        <velocimeter noise="0.01" site="FRAME" name="body_vel"/>

        <!-- Position sensor for the body -->

        <!-- Indices 21, 22, 23 -->
        <framepos objtype="site" objname="FRAME" name="body_pos"/>
         <!-- Indices 24, 25, 26, 27 -->
        <framequat objtype="site" objname="FRAME" name="body_quat"/>
        <!-- Indices 28, 29, 30 -->
        <framelinvel objtype="site" objname="FRAME" name="body_linvel"/>
        <!-- Indices 31, 32, 33 -->
        <framexaxis objtype="site" objname="FRAME" name="body_xaxis"/>
        <!-- Indices 34, 35, 36 -->
        <framezaxis objtype="site" objname="FRAME" name="body_zaxis"/>


    </sensor>
</mujoco>